0913/output/reference_anchor_results.json
{
  "gamma_5": {
    "2026-07-03": {
      "through": {
        "date": "2026-07-03",
        "strategy": "gp_qvi",
        "fill_mode": "through",
        "tick_hkd": 0.05,
        "quote_decisions": 4888,
        "quoted_bid": 9,
        "quoted_ask": 9,
        "maker_fills": 14,
        "buy_fills": 8,
        "sell_fills": 6,
        "trade_price_fills": 14,
        "best_quote_fills": 0,
        "best_ask_fills": 0,
        "best_bid_fills": 0,
        "bid_cancels": 1,
        "ask_cancels": 3,
        "expired_orders": 4,
        "market_orders": 4,
        "market_order_lots": 4,
        "policy_market_orders": 4,
        "policy_market_order_lots": 4,
        "terminal_flatten_orders": 0,
        "terminal_flatten_side": "none",
        "terminal_flatten_lots": 0,
        "end_inventory_lots": 0,
        "max_abs_inventory_lots": 1,
        "gross_pnl_hkd": 99.99832153320312,
        "official_only_fees_hkd": 26.122629825592046,
        "all_in_fees_hkd": 56.97612961959839,
        "net_pnl_official_only_hkd": 73.87569170761108,
        "net_pnl_hkd": 43.022191913604736,
        "maker_turnover_hkd": 158814.99862670898,
        "market_turnover_hkd": 46875.0,
        "feeable_turnover_hkd": 205689.99862670898,
        "gross_bps_of_feeable_turnover": 4.861603490730846,
        "net_bps_of_feeable_turnover": 2.091603490730846,
        "max_drawdown_hkd": 26.415777721405032
      },
      "touch": {
        "date": "2026-07-03",
        "strategy": "gp_qvi",
        "fill_mode": "touch",
        "tick_hkd": 0.05,
        "quote_decisions": 4888,
        "quoted_bid": 117,
        "quoted_ask": 117,
        "maker_fills": 164,
        "buy_fills": 85,
        "sell_fills": 79,
        "trade_price_fills": 147,
        "best_quote_fills": 17,
        "best_ask_fills": 9,
        "best_bid_fills": 8,
        "bid_cancels": 32,
        "ask_cancels": 38,
        "expired_orders": 70,
        "market_orders": 68,
        "market_order_lots": 68,
        "policy_market_orders": 68,
        "policy_market_order_lots": 68,
        "terminal_flatten_orders": 0,
        "terminal_flatten_side": "none",
        "terminal_flatten_lots": 0,
        "end_inventory_lots": 0,
        "max_abs_inventory_lots": 1,
        "gross_pnl_hkd": 139.99786376953125,
        "official_only_fees_hkd": 339.56370926361075,
        "all_in_fees_hkd": 740.6232083938597,
        "net_pnl_official_only_hkd": -199.5658454940795,
        "net_pnl_hkd": -600.6253446243285,
        "maker_turnover_hkd": 1889089.9963378906,
        "market_turnover_hkd": 784639.9978637695,
        "feeable_turnover_hkd": 2673729.99420166,
        "gross_bps_of_feeable_turnover": 0.5236050912887064,
        "net_bps_of_feeable_turnover": -2.246394908711293,
        "max_drawdown_hkd": 657.9441074302672
      }
    },
    "2026-07-06": {
      "through": {
        "date": "2026-07-06",
        "strategy": "gp_qvi",
        "fill_mode": "through",
        "tick_hkd": 0.05,
        "quote_decisions": 4348,
        "quoted_bid": 14,
        "quoted_ask": 14,
        "maker_fills": 18,
        "buy_fills": 8,
        "sell_fills": 10,
        "trade_price_fills": 18,
        "best_quote_fills": 0,
        "best_ask_fills": 0,
        "best_bid_fills": 0,
        "bid_cancels": 6,
        "ask_cancels": 4,
        "expired_orders": 10,
        "market_orders": 8,
        "market_order_lots": 8,
        "policy_market_orders": 8,
        "policy_market_order_lots": 8,
        "terminal_flatten_orders": 0,
        "terminal_flatten_side": "none",
        "terminal_flatten_lots": 0,
        "end_inventory_lots": 0,
        "max_abs_inventory_lots": 1,
        "gross_pnl_hkd": 40.001068115234375,
        "official_only_fees_hkd": 37.29990013565063,
        "all_in_fees_hkd": 81.35490029586792,
        "net_pnl_official_only_hkd": 2.7011679795837438,
        "net_pnl_hkd": -41.353832180633546,
        "maker_turnover_hkd": 203885.00091552734,
        "market_turnover_hkd": 89815.00015258789,
        "feeable_turnover_hkd": 293700.00106811523,
        "gross_bps_of_feeable_turnover": 1.3619703088103594,
        "net_bps_of_feeable_turnover": -1.4080296911896406,
        "max_drawdown_hkd": 97.56983490203856
      },
      "touch": {
        "date": "2026-07-06",
        "strategy": "gp_qvi",
        "fill_mode": "touch",
        "tick_hkd": 0.05,
        "quote_decisions": 4348,
        "quoted_bid": 91,
        "quoted_ask": 91,
        "maker_fills": 114,
        "buy_fills": 58,
        "sell_fills": 56,
        "trade_price_fills": 98,
        "best_quote_fills": 16,
        "best_ask_fills": 9,
        "best_bid_fills": 7,
        "bid_cancels": 33,
        "ask_cancels": 35,
        "expired_orders": 68,
        "market_orders": 60,
        "market_order_lots": 60,
        "policy_market_orders": 60,
        "policy_market_order_lots": 60,
        "terminal_flatten_orders": 0,
        "terminal_flatten_side": "none",
        "terminal_flatten_lots": 0,
        "end_inventory_lots": 0,
        "max_abs_inventory_lots": 1,
        "gross_pnl_hkd": -40.007781982421875,
        "official_only_fees_hkd": 241.76989970932007,
        "all_in_fees_hkd": 527.3248993659975,
        "net_pnl_official_only_hkd": -281.7776816917419,
        "net_pnl_hkd": -567.3326813484193,
        "maker_turnover_hkd": 1250319.9981689453,
        "market_turnover_hkd": 653379.9995422363,
        "feeable_turnover_hkd": 1903699.9977111816,
        "gross_bps_of_feeable_turnover": -0.21015801875570325,
        "net_bps_of_feeable_turnover": -2.980158018755704,
        "max_drawdown_hkd": 652.4181996749878
      }
    },
    "2026-07-07": {
      "through": {
        "date": "2026-07-07",
        "strategy": "gp_qvi",
        "fill_mode": "through",
        "tick_hkd": 0.02,
        "quote_decisions": 7603,
        "quoted_bid": 12,
        "quoted_ask": 12,
        "maker_fills": 16,
        "buy_fills": 8,
        "sell_fills": 8,
        "trade_price_fills": 15,
        "best_quote_fills": 1,
        "best_ask_fills": 0,
        "best_bid_fills": 1,
        "bid_cancels": 4,
        "ask_cancels": 4,
        "expired_orders": 8,
        "market_orders": 6,
        "market_order_lots": 6,
        "policy_market_orders": 6,
        "policy_market_order_lots": 6,
        "terminal_flatten_orders": 0,
        "terminal_flatten_side": "none",
        "terminal_flatten_lots": 0,
        "end_inventory_lots": 0,
        "max_abs_inventory_lots": 1,
        "gross_pnl_hkd": 58.00018310546875,
        "official_only_fees_hkd": 25.723850193786625,
        "all_in_fees_hkd": 56.106350422668456,
        "net_pnl_official_only_hkd": 32.276332911682125,
        "net_pnl_hkd": 1.8938326828002943,
        "maker_turnover_hkd": 146952.0004272461,
        "market_turnover_hkd": 55598.00109863281,
        "feeable_turnover_hkd": 202550.0015258789,
        "gross_bps_of_feeable_turnover": 2.8634995146153246,
        "net_bps_of_feeable_turnover": 0.09349951461532464,
        "max_drawdown_hkd": 27.708034687042232
      },
      "touch": {
        "date": "2026-07-07",
        "strategy": "gp_qvi",
        "fill_mode": "touch",
        "tick_hkd": 0.02,
        "quote_decisions": 7603,
        "quoted_bid": 198,
        "quoted_ask": 198,
        "maker_fills": 244,
        "buy_fills": 113,
        "sell_fills": 131,
        "trade_price_fills": 229,
        "best_quote_fills": 15,
        "best_ask_fills": 7,
        "best_bid_fills": 8,
        "bid_cancels": 85,
        "ask_cancels": 67,
        "expired_orders": 152,
        "market_orders": 136,
        "market_order_lots": 136,
        "policy_market_orders": 136,
        "policy_market_order_lots": 136,
        "terminal_flatten_orders": 0,
        "terminal_flatten_side": "none",
        "terminal_flatten_lots": 0,
        "end_inventory_lots": 0,
        "max_abs_inventory_lots": 1,
        "gross_pnl_hkd": -250.00152587890625,
        "official_only_fees_hkd": 441.99174999999985,
        "all_in_fees_hkd": 964.0292499999993,
