output/results/7709_state_example.json
{
  "description": "Two adjacent reconstructed HK 7709 ten-level snapshots used to explain one DeepLOB state.",
  "source": "/Users/jiaqianxing/Documents/GitHub/DeepLOB-Deep-Convolutional-Neural-Networks-for-Limit-Order-Books/data/processed/hk07709_2026-07-09_lob.npz",
  "security_id": 7709,
  "feature_order": "ask_price,ask_size,bid_price,bid_size repeated for 10 levels",
  "feature_scale": 100000.0,
  "snapshot_every_book_update_groups": 10,
  "delta_milliseconds": 31.0,
  "states": [
    {
      "state": "t",
      "state_order": 1,
      "snapshot_index": 27802,
      "send_time": 20260709101008341,
      "send_time_readable": "2026-07-09 10:10:08.341",
      "model_vector": [
        0.89780003,
        0.034,
        0.8976,
        0.007,
        0.89840001,
        0.048,
        0.89740002,
        0.01,
        0.89859998,
        0.008,
        0.89719999,
        0.01,
        0.89880002,
        0.008,
        0.89700001,
        0.01,
        0.89899999,
        0.008,
        0.89679998,
        0.009,
        0.89920002,
        0.022,
        0.89660001,
        0.01,
        0.8994,
        0.041,
        0.89639997,
        0.034,
        0.89960003,
        0.001,
        0.8962,
        0.084,
        0.8998,
        0.004,
        0.89600003,
        0.001,
        0.89999998,
        0.099,
        0.89579999,
        0.001
      ]
    },
    {
      "state": "t+1",
      "state_order": 2,
      "snapshot_index": 27803,
      "send_time": 20260709101008372,
      "send_time_readable": "2026-07-09 10:10:08.372",
      "model_vector": [
        0.89880002,
        0.004,
        0.89840001,
        0.014,
        0.89899999,
        0.008,
        0.89819998,
        0.007,
        0.89920002,
        0.042,
        0.898,
        0.017,
        0.8994,
        0.041,
        0.89780003,
        0.01,
        0.89960003,
        0.001,
        0.8976,
        0.016,
        0.8998,
        0.004,
        0.89740002,
        0.01,
        0.89999998,
        0.029,
        0.89719999,
        0.01,
        0.90020001,
        0.025,
        0.89700001,
        0.01,
        0.90060002,
        0.024,
        0.89679998,
        0.009,
        0.90079999,
        0.018,
        0.89660001,
        0.01
      ]
    }
  ],
  "rows": [
    {
      "row_order": 1,
      "state": "t",
      "send_time": 20260709101008341,
      "time": "10:10:08.341",
      "level": "L1",
      "ask_price_hkd": 0.8978,
      "ask_size_units": 3400,
      "bid_price_hkd": 0.8976,
      "bid_size_units": 700,
      "model_input_slice": "[0.8978, 0.0340, 0.8976, 0.0070]"
    },
    {
      "row_order": 2,
      "state": "t",
      "send_time": 20260709101008341,
      "time": "10:10:08.341",
      "level": "L2",
      "ask_price_hkd": 0.8984,
      "ask_size_units": 4800,
      "bid_price_hkd": 0.8974,
      "bid_size_units": 1000,
      "model_input_slice": "[0.8984, 0.0480, 0.8974, 0.0100]"
    },
    {
      "row_order": 3,
      "state": "t",
      "send_time": 20260709101008341,
      "time": "10:10:08.341",
      "level": "L3",
      "ask_price_hkd": 0.8986,
      "ask_size_units": 800,
      "bid_price_hkd": 0.8972,
      "bid_size_units": 1000,
      "model_input_slice": "[0.8986, 0.0080, 0.8972, 0.0100]"
    },
    {
      "row_order": 4,
      "state": "t",
      "send_time": 20260709101008341,
      "time": "10:10:08.341",
      "level": "L4",
      "ask_price_hkd": 0.8988,
      "ask_size_units": 800,
      "bid_price_hkd": 0.897,
      "bid_size_units": 1000,
      "model_input_slice": "[0.8988, 0.0080, 0.8970, 0.0100]"
    },
    {
      "row_order": 5,
      "state": "t",
      "send_time": 20260709101008341,
      "time": "10:10:08.341",
      "level": "L5",
      "ask_price_hkd": 0.899,
      "ask_size_units": 800,
      "bid_price_hkd": 0.8968,
      "bid_size_units": 900,
      "model_input_slice": "[0.8990, 0.0080, 0.8968, 0.0090]"
    },
    {
      "row_order": 6,
      "state": "t",
      "send_time": 20260709101008341,
      "time": "10:10:08.341",
      "level": "L6",
      "ask_price_hkd": 0.8992,
      "ask_size_units": 2200,
      "bid_price_hkd": 0.8966,
      "bid_size_units": 1000,
      "model_input_slice": "[0.8992, 0.0220, 0.8966, 0.0100]"
    },
    {
      "row_order": 7,
      "state": "t",
      "send_time": 20260709101008341,
      "time": "10:10:08.341",
      "level": "L7",
      "ask_price_hkd": 0.8994,
      "ask_size_units": 4100,
      "bid_price_hkd": 0.8964,
      "bid_size_units": 3400,
      "model_input_slice": "[0.8994, 0.0410, 0.8964, 0.0340]"
    },
    {
      "row_order": 8,
      "state": "t",
      "send_time": 20260709101008341,
      "time": "10:10:08.341",
      "level": "L8",
      "ask_price_hkd": 0.8996,
      "ask_size_units": 100,
      "bid_price_hkd": 0.8962,
      "bid_size_units": 8400,
      "model_input_slice": "[0.8996, 0.0010, 0.8962, 0.0840]"
    },
    {
      "row_order": 9,
      "state": "t",
      "send_time": 20260709101008341,
      "time": "10:10:08.341",
      "level": "L9",
      "ask_price_hkd": 0.8998,
      "ask_size_units": 400,
      "bid_price_hkd": 0.896,
      "bid_size_units": 100,
      "model_input_slice": "[0.8998, 0.0040, 0.8960, 0.0010]"
    },
    {
      "row_order": 10,
      "state": "t",
      "send_time": 20260709101008341,
      "time": "10:10:08.341",
      "level": "L10",
      "ask_price_hkd": 0.9,
      "ask_size_units": 9900,
      "bid_price_hkd": 0.8958,
      "bid_size_units": 100,
      "model_input_slice": "[0.9000, 0.0990, 0.8958, 0.0010]"
    },
    {
      "row_order": 11,
      "state": "t+1",
      "send_time": 20260709101008372,
      "time": "10:10:08.372",
      "level": "L1",
      "ask_price_hkd": 0.8988,
      "ask_size_units": 400,
      "bid_price_hkd": 0.8984,
      "bid_size_units": 1400,
      "model_input_slice": "[0.8988, 0.0040, 0.8984, 0.0140]"
    },
    {
      "row_order": 12,
      "state": "t+1",
      "send_time": 20260709101008372,
      "time": "10:10:08.372",
      "level": "L2",
      "ask_price_hkd": 0.899,
      "ask_size_units": 800,
      "bid_price_hkd": 0.8982,
      "bid_size_units": 700,
      "model_input_slice": "[0.8990, 0.0080, 0.8982, 0.0070]"
    },
    {
      "row_order": 13,
      "state": "t+1",
      "send_time": 20260709101008372,
      "time": "10:10:08.372",
      "level": "L3",
      "ask_price_hkd": 0.8992,
      "ask_size_units": 4200,
      "bid_price_hkd": 0.898,
      "bid_size_units": 1700,
      "model_input_slice": "[0.8992, 0.0420, 0.8980, 0.0170]"
    },
    {
      "row_order": 14,
      "state": "t+1",
      "send_time": 20260709101008372,
      "time": "10:10:08.372",
      "level": "L4",
      "ask_price_hkd": 0.8994,
      "ask_size_units": 4100,
      "bid_price_hkd": 0.8978,
      "bid_size_units": 1000,
      "model_input_slice": "[0.8994, 0.0410, 0.8978, 0.0100]"
    },
    {
      "row_order": 15,
      "state": "t+1",
      "send_time": 20260709101008372,
      "time": "10:10:08.372",
      "level": "L5",
      "ask_price_hkd": 0.8996,
      "ask_size_units": 100,
      "bid_price_hkd": 0.8976,
      "bid_size_units": 1600,
      "model_input_slice": "[0.8996, 0.0010, 0.8976, 0.0160]"
    },
    {
      "row_order": 16,
      "state": "t+1",
      "send_time": 20260709101008372,
      "time": "10:10:08.372",
      "level": "L6",
      "ask_price_hkd": 0.8998,
      "ask_size_units": 400,
      "bid_price_hkd": 0.8974,
      "bid_size_units": 1000,
      "model_input_slice": "[0.8998, 0.0040, 0.8974, 0.0100]"
    },
    {
      "row_order": 17,
      "state": "t+1",
      "send_time": 20260709101008372,
      "time": "10:10:08.372",
      "level": "L7",
      "ask_price_hkd": 0.9,
      "ask_size_units": 2900,
      "bid_price_hkd": 0.8972,
      "bid_size_units": 1000,
      "model_input_slice": "[0.9000, 0.0290, 0.8972, 0.0100]"
    },
    {
      "row_order": 18,
      "state": "t+1",
      "send_time": 20260709101008372,
      "time": "10:10:08.372",
      "level": "L8",
